Traceback (most recent call last):
  File "/home/jpmunoz/AutoML/Phuong/fedtext_env/lib/python3.11/site-packages/urllib3/connection.py", line 198, in _new_conn
    sock = connection.create_connection(
           ^^^^^^^^^^^^^^^^^^^^^^^^^^^^^
  File "/home/jpmunoz/AutoML/Phuong/fedtext_env/lib/python3.11/site-packages/urllib3/util/connection.py", line 60, in create_connection
    for res in socket.getaddrinfo(host, port, family, socket.SOCK_STREAM):
               ^^^^^^^^^^^^^^^^^^^^^^^^^^^^^^^^^^^^^^^^^^^^^^^^^^^^^^^^^^
  File "/home/jpmunoz/Python-3.11.1-install/lib/python3.11/socket.py", line 962, in getaddrinfo
    for res in _socket.getaddrinfo(host, port, family, type, proto, flags):
               ^^^^^^^^^^^^^^^^^^^^^^^^^^^^^^^^^^^^^^^^^^^^^^^^^^^^^^^^^^^
socket.gaierror: [Errno -3] Temporary failure in name resolution

The above exception was the direct cause of the following exception:

Traceback (most recent call last):
  File "/home/jpmunoz/AutoML/Phuong/fedtext_env/lib/python3.11/site-packages/urllib3/connectionpool.py", line 779, in urlopen
    self._prepare_proxy(conn)
  File "/home/jpmunoz/AutoML/Phuong/fedtext_env/lib/python3.11/site-packages/urllib3/connectionpool.py", line 1048, in _prepare_proxy
    conn.connect()
  File "/home/jpmunoz/AutoML/Phuong/fedtext_env/lib/python3.11/site-packages/urllib3/connection.py", line 616, in connect
    self.sock = sock = self._new_conn()
                       ^^^^^^^^^^^^^^^^
  File "/home/jpmunoz/AutoML/Phuong/fedtext_env/lib/python3.11/site-packages/urllib3/connection.py", line 205, in _new_conn
    raise NameResolutionError(self.host, self, e) from e
urllib3.exceptions.NameResolutionError: <urllib3.connection.HTTPSConnection object at 0x7fb3dc9cd990>: Failed to resolve 'proxy-us.intel.com' ([Errno -3] Temporary failure in name resolution)

The above exception was the direct cause of the following exception:

urllib3.exceptions.ProxyError: ('Unable to connect to proxy', NameResolutionError("<urllib3.connection.HTTPSConnection object at 0x7fb3dc9cd990>: Failed to resolve 'proxy-us.intel.com' ([Errno -3] Temporary failure in name resolution)"))

The above exception was the direct cause of the following exception:

Traceback (most recent call last):
  File "/home/jpmunoz/AutoML/Phuong/fedtext_env/lib/python3.11/site-packages/requests/adapters.py", line 667, in send
    resp = conn.urlopen(
           ^^^^^^^^^^^^^
  File "/home/jpmunoz/AutoML/Phuong/fedtext_env/lib/python3.11/site-packages/urllib3/connectionpool.py", line 847, in urlopen
    retries = retries.increment(
              ^^^^^^^^^^^^^^^^^^
  File "/home/jpmunoz/AutoML/Phuong/fedtext_env/lib/python3.11/site-packages/urllib3/util/retry.py", line 515, in increment
    raise MaxRetryError(_pool, url, reason) from reason  # type: ignore[arg-type]
    ^^^^^^^^^^^^^^^^^^^^^^^^^^^^^^^^^^^^^^^^^^^^^^^^^^^
urllib3.exceptions.MaxRetryError: HTTPSConnectionPool(host='huggingface.co', port=443): Max retries exceeded with url: /distilbert-base-uncased/resolve/main/tokenizer_config.json (Caused by ProxyError('Unable to connect to proxy', NameResolutionError("<urllib3.connection.HTTPSConnection object at 0x7fb3dc9cd990>: Failed to resolve 'proxy-us.intel.com' ([Errno -3] Temporary failure in name resolution)")))

During handling of the above exception, another exception occurred:

Traceback (most recent call last):
  File "/home/jpmunoz/AutoML/Phuong/fedtext/system/main.py", line 29, in <module>
    from flcore.servers.serverlora import FLora
  File "/home/jpmunoz/AutoML/Phuong/fedtext/system/flcore/servers/serverlora.py", line 21, in <module>
    from flcore.clients.clientlora import clientLORA
  File "/home/jpmunoz/AutoML/Phuong/fedtext/system/flcore/clients/clientlora.py", line 23, in <module>
    from flcore.clients.clientbase import Client
  File "/home/jpmunoz/AutoML/Phuong/fedtext/system/flcore/clients/clientbase.py", line 26, in <module>
    from utils.data_utils import read_data
  File "/home/jpmunoz/AutoML/Phuong/fedtext/system/utils/data_utils.py", line 18, in <module>
    tokenizer = AutoTokenizer.from_pretrained(checkpoint)
                ^^^^^^^^^^^^^^^^^^^^^^^^^^^^^^^^^^^^^^^^^
  File "/home/jpmunoz/AutoML/Phuong/fedtext_env/lib/python3.11/site-packages/transformers/models/auto/tokenization_auto.py", line 817, in from_pretrained
    tokenizer_config = get_tokenizer_config(pretrained_model_name_or_path, **kwargs)
                       ^^^^^^^^^^^^^^^^^^^^^^^^^^^^^^^^^^^^^^^^^^^^^^^^^^^^^^^^^^^^^
  File "/home/jpmunoz/AutoML/Phuong/fedtext_env/lib/python3.11/site-packages/transformers/models/auto/tokenization_auto.py", line 649, in get_tokenizer_config
    resolved_config_file = cached_file(
                           ^^^^^^^^^^^^
  File "/home/jpmunoz/AutoML/Phuong/fedtext_env/lib/python3.11/site-packages/transformers/utils/hub.py", line 399, in cached_file
    resolved_file = hf_hub_download(
                    ^^^^^^^^^^^^^^^^
  File "/home/jpmunoz/AutoML/Phuong/fedtext_env/lib/python3.11/site-packages/huggingface_hub/utils/_validators.py", line 114, in _inner_fn
    return fn(*args, **kwargs)
           ^^^^^^^^^^^^^^^^^^^
  File "/home/jpmunoz/AutoML/Phuong/fedtext_env/lib/python3.11/site-packages/huggingface_hub/file_download.py", line 1221, in hf_hub_download
    return _hf_hub_download_to_cache_dir(
           ^^^^^^^^^^^^^^^^^^^^^^^^^^^^^^
  File "/home/jpmunoz/AutoML/Phuong/fedtext_env/lib/python3.11/site-packages/huggingface_hub/file_download.py", line 1282, in _hf_hub_download_to_cache_dir
    (url_to_download, etag, commit_hash, expected_size, head_call_error) = _get_metadata_or_catch_error(
                                                                           ^^^^^^^^^^^^^^^^^^^^^^^^^^^^^
  File "/home/jpmunoz/AutoML/Phuong/fedtext_env/lib/python3.11/site-packages/huggingface_hub/file_download.py", line 1722, in _get_metadata_or_catch_error
    metadata = get_hf_file_metadata(url=url, proxies=proxies, timeout=etag_timeout, headers=headers)
               ^^^^^^^^^^^^^^^^^^^^^^^^^^^^^^^^^^^^^^^^^^^^^^^^^^^^^^^^^^^^^^^^^^^^^^^^^^^^^^^^^^^^^
  File "/home/jpmunoz/AutoML/Phuong/fedtext_env/lib/python3.11/site-packages/huggingface_hub/utils/_validators.py", line 114, in _inner_fn
    return fn(*args, **kwargs)
           ^^^^^^^^^^^^^^^^^^^
  File "/home/jpmunoz/AutoML/Phuong/fedtext_env/lib/python3.11/site-packages/huggingface_hub/file_download.py", line 1645, in get_hf_file_metadata
    r = _request_wrapper(
        ^^^^^^^^^^^^^^^^^
  File "/home/jpmunoz/AutoML/Phuong/fedtext_env/lib/python3.11/site-packages/huggingface_hub/file_download.py", line 372, in _request_wrapper
    response = _request_wrapper(
               ^^^^^^^^^^^^^^^^^
  File "/home/jpmunoz/AutoML/Phuong/fedtext_env/lib/python3.11/site-packages/huggingface_hub/file_download.py", line 395, in _request_wrapper
    response = get_session().request(method=method, url=url, **params)
               ^^^^^^^^^^^^^^^^^^^^^^^^^^^^^^^^^^^^^^^^^^^^^^^^^^^^^^^
  File "/home/jpmunoz/AutoML/Phuong/fedtext_env/lib/python3.11/site-packages/requests/sessions.py", line 589, in request
    resp = self.send(prep, **send_kwargs)
           ^^^^^^^^^^^^^^^^^^^^^^^^^^^^^^
  File "/home/jpmunoz/AutoML/Phuong/fedtext_env/lib/python3.11/site-packages/requests/sessions.py", line 703, in send
    r = adapter.send(request, **kwargs)
        ^^^^^^^^^^^^^^^^^^^^^^^^^^^^^^^
  File "/home/jpmunoz/AutoML/Phuong/fedtext_env/lib/python3.11/site-packages/huggingface_hub/utils/_http.py", line 66, in send
    return super().send(request, *args, **kwargs)
           ^^^^^^^^^^^^^^^^^^^^^^^^^^^^^^^^^^^^^^
  File "/home/jpmunoz/AutoML/Phuong/fedtext_env/lib/python3.11/site-packages/requests/adapters.py", line 694, in send
    raise ProxyError(e, request=request)
requests.exceptions.ProxyError: (MaxRetryError('HTTPSConnectionPool(host=\'huggingface.co\', port=443): Max retries exceeded with url: /distilbert-base-uncased/resolve/main/tokenizer_config.json (Caused by ProxyError(\'Unable to connect to proxy\', NameResolutionError("<urllib3.connection.HTTPSConnection object at 0x7fb3dc9cd990>: Failed to resolve \'proxy-us.intel.com\' ([Errno -3] Temporary failure in name resolution)")))'), '(Request ID: f212794f-34c0-4026-9ab2-860c83827150)')

real	0m21.338s
user	0m14.032s
sys	0m7.484s
